Workbook

Sheet Summary
A1: Black-Box Test Cases: Logistics Modules (L1–L8)
A2: Multi-role e-commerce and logistics platform (Buyer, Seller, Logistics, Rider)
A4: Test run details
A5: System under test
A6: Version / build
A7: Test environment (browser, device)
A8: Tester
A9: Date tested
A11: Results by module
A12: Module (sheet) | B12: Total test cases | C12: Pass | D12: Fail | E12: Blocked | F12: Not Run | G12: Pass rate (Pass / Total)
A13: L1 Dashboard | B13: =COUNTA('L1 Dashboard'!$A$2:$A$200) | C13: =COUNTIF('L1 Dashboard'!$L$2:$L$200,"Pass") | D13: =COUNTIF('L1 Dashboard'!$L$2:$L$200,"Fail") | E13: =COUNTIF('L1 Dashboard'!$L$2:$L$200,"Blocked") | F13: =COUNTIF('L1 Dashboard'!$L$2:$L$200,"Not Run") | G13: =IF(B13=0,0,C13/B13)
A14: L2 Rider Mgmt | B14: =COUNTA('L2 Rider Mgmt'!$A$2:$A$200) | C14: =COUNTIF('L2 Rider Mgmt'!$L$2:$L$200,"Pass") | D14: =COUNTIF('L2 Rider Mgmt'!$L$2:$L$200,"Fail") | E14: =COUNTIF('L2 Rider Mgmt'!$L$2:$L$200,"Blocked") | F14: =COUNTIF('L2 Rider Mgmt'!$L$2:$L$200,"Not Run") | G14: =IF(B14=0,0,C14/B14)
A15: L3 Dispatch | B15: =COUNTA('L3 Dispatch'!$A$2:$A$200) | C15: =COUNTIF('L3 Dispatch'!$L$2:$L$200,"Pass") | D15: =COUNTIF('L3 Dispatch'!$L$2:$L$200,"Fail") | E15: =COUNTIF('L3 Dispatch'!$L$2:$L$200,"Blocked") | F15: =COUNTIF('L3 Dispatch'!$L$2:$L$200,"Not Run") | G15: =IF(B15=0,0,C15/B15)
A16: L4 Hub Ops | B16: =COUNTA('L4 Hub Ops'!$A$2:$A$200) | C16: =COUNTIF('L4 Hub Ops'!$L$2:$L$200,"Pass") | D16: =COUNTIF('L4 Hub Ops'!$L$2:$L$200,"Fail") | E16: =COUNTIF('L4 Hub Ops'!$L$2:$L$200,"Blocked") | F16: =COUNTIF('L4 Hub Ops'!$L$2:$L$200,"Not Run") | G16: =IF(B16=0,0,C16/B16)
A17: L5 Tracking & Exceptions | B17: =COUNTA('L5 Tracking & Exceptions'!$A$2:$A$200) | C17: =COUNTIF('L5 Tracking & Exceptions'!$L$2:$L$200,"Pass") | D17: =COUNTIF('L5 Tracking & Exceptions'!$L$2:$L$200,"Fail") | E17: =COUNTIF('L5 Tracking & Exceptions'!$L$2:$L$200,"Blocked") | F17: =COUNTIF('L5 Tracking & Exceptions'!$L$2:$L$200,"Not Run") | G17: =IF(B17=0,0,C17/B17)
A18: L6 Returns (RTS) | B18: =COUNTA('L6 Returns (RTS)'!$A$2:$A$200) | C18: =COUNTIF('L6 Returns (RTS)'!$L$2:$L$200,"Pass") | D18: =COUNTIF('L6 Returns (RTS)'!$L$2:$L$200,"Fail") | E18: =COUNTIF('L6 Returns (RTS)'!$L$2:$L$200,"Blocked") | F18: =COUNTIF('L6 Returns (RTS)'!$L$2:$L$200,"Not Run") | G18: =IF(B18=0,0,C18/B18)
A19: L7 Zones & Rates | B19: =COUNTA('L7 Zones & Rates'!$A$2:$A$200) | C19: =COUNTIF('L7 Zones & Rates'!$L$2:$L$200,"Pass") | D19: =COUNTIF('L7 Zones & Rates'!$L$2:$L$200,"Fail") | E19: =COUNTIF('L7 Zones & Rates'!$L$2:$L$200,"Blocked") | F19: =COUNTIF('L7 Zones & Rates'!$L$2:$L$200,"Not Run") | G19: =IF(B19=0,0,C19/B19)
A20: L8 COD & Reports | B20: =COUNTA('L8 COD & Reports'!$A$2:$A$200) | C20: =COUNTIF('L8 COD & Reports'!$L$2:$L$200,"Pass") | D20: =COUNTIF('L8 COD & Reports'!$L$2:$L$200,"Fail") | E20: =COUNTIF('L8 COD & Reports'!$L$2:$L$200,"Blocked") | F20: =COUNTIF('L8 COD & Reports'!$L$2:$L$200,"Not Run") | G20: =IF(B20=0,0,C20/B20)
A21: Total | B21: =SUM(B13:B20) | C21: =SUM(C13:C20) | D21: =SUM(D13:D20) | E21: =SUM(E13:E20) | F21: =SUM(F13:F20) | G21: =IF(B21=0,0,C21/B21)
A23: How to use this workbook
A24: 1. Logistics cases need parcels from the Seller and Buyer test sets and riders from the Account Creation set.
A25: 2. Strict pass rule: a case passes only if EVERY point in its Expected Result is true. If any point is false, or something happens that the Expected Result does not mention (an extra record, a stock change, a wrong notification, a console error, a 500 page), mark it Fail.
A26: 3. Check side effects, not just the screen: after each case, confirm the stock, order status, voucher usage, balances and the other roles' views named in the Expected Result. 'Nothing is saved' means the record is missing after a page refresh.
A27: 4. Error messages must appear next to the field (or at the top of the form) and say what is wrong and how to fix it. A generic 'Something went wrong', a blank page, or a 500 error is a Fail even when the action was correctly blocked.
A28: 5. For 'Error Guessing' security cases, a correct block shows a 403 page, a 'not found' page or a redirect, and shows NO data from the other user's record anywhere on the page.
A29: 6. Read the Assumptions sheet first. Rules A2 to A8 are the seven rules the module plan says must be agreed before testing; adjust any case whose rule differs from your system.
A30: 7. Seed the accounts, products, vouchers and shipping rates on the Test Data sheet before running the cases. Emails use example.com; read them from a mail catcher such as Mailtrap.
A31: 8. Test Case IDs follow <ROLE>-<MODULE>-<NNN>. Each module has positive, negative and boundary cases.
A32: 9. Fill in only the yellow cells: Actual Result, Status and Remarks. Pick the Status from the dropdown (Pass, Fail, Blocked, Not Run).
A33: 10. Pass = actual matches expected. Fail = it does not (describe what happened and add a screenshot or bug number in Remarks). Blocked = the case could not be run, for example because an earlier case failed.
A34: 11. The Results by module table above updates automatically from the Status column.
A36: Black-box techniques used
A37: Equivalence Partitioning | B37: Inputs are grouped into valid and invalid classes, and one value from each class is tested.
A38: Boundary Value Analysis | B38: Values at and just beyond a limit are tested, for example ₱0.99, ₱1.00 and ₱1.01 for a ₱1.00 minimum price.
A39: Decision Table | B39: Combinations of conditions are tested, for example which vouchers can stack.
A40: State Transition | B40: Changes in order or shipment status are tested, including transitions that must be blocked.
A41: Use Case Testing | B41: A complete user flow is tested from start to finish with valid data.
A42: Error Guessing | B42: Likely mistakes are tested based on experience, for example double-clicking Place Order or editing an ID in the URL.

Sheet Assumptions
A1: Assumptions used in the test cases
A2: These rules are assumptions modeled on Philippine marketplaces, not taken from your actual system. Rules A2 to A8 are the seven rules the module plan says must be agreed before testing; A25 to A37 fix the limits the strict expected results depend on. Write your real rule in column D where it differs, then filter the Assumption Ref column on each module sheet to find the test cases to adjust.
A4: Ref | B4: Topic | C4: Assumed rule | D4: Your system's actual rule (fill in if different)
A5: A1 | B5: Test accounts | C5: The accounts on the Test Data sheet already exist and are Active or Approved (they are the accounts created in the Account Creation test set). Seller 3 is Pending Approval and Rider 3 is Suspended, for the negative cases. Reset the seeded products, stock and vouchers to their Test Data values before each module.
A6: A2 | B6: Voucher stacking (rule 1) | C6: Per order: at most 1 store voucher per store, plus 1 platform voucher, plus 1 shipping voucher. Selecting a second voucher of the same type replaces the first; it never stacks.
A7: A3 | B7: Stock deduction (rule 2) | C7: Stock is deducted when the order is placed, for every payment method. It is restored when the order is cancelled (by buyer, seller or auto-cancel). For a Return-to-Sender or returned parcel, stock is restored when the seller confirms receipt. Stock can never go below 0.
A8: A4 | B8: Sale + voucher (rule 3) | C8: Vouchers apply to items already on sale. Minimum spend is checked against the price actually paid (the sale or flash price), not the original price.
A9: A5 | B9: Flash sales (rule 4) | C9: Sellers create flash sales for their own products in fixed time slots. When a product is in both a store sale and a flash sale, the flash price wins while flash quantity remains. Units beyond the remaining flash quantity in the same order are charged at the store sale price, or the regular price if there is no sale, and are shown on a separate line.
A10: A6 | B10: Cancellation window and auto-cancel (rule 5) | C10: A buyer can cancel until the seller marks the order Ready for Pickup; after that there is no cancel option at all. A seller can cancel until the parcel is Picked Up. Unpaid e-wallet or card orders auto-cancel exactly 1 hour after the order is placed.
A11: A7 | B11: Variation limits and category depth (rule 6) | C11: A product has at most 2 variation types, with 1 to 20 options per type. Store categories have at most 2 levels (category and subcategory). A product can belong to up to 3 store categories.
A12: A8 | B12: Voucher funding (rule 7) | C12: Store vouchers, sale discounts, flash sales and bundle discounts are seller-funded. Platform vouchers and shipping vouchers are platform-funded and never reduce the seller's earnings. A platform voucher on a multi-store checkout is split across the store orders in proportion to each store's merchandise subtotal, rounded to the centavo, with any rounding remainder given to the largest store. When only some items in an order are refunded, the store voucher is split across the items in proportion to their price, and the refund is the item price minus its voucher share.
A13: A9 | B13: Platform commission and rounding | C13: Commission is 5% of the item subtotal after seller-funded discounts. Shipping fees are not part of the seller's gross sales. All money is rounded to 2 decimals (half up) per order.
A14: A10 | B14: Order status flow | C14: Buyer tabs: To Pay → To Ship → To Receive → Completed (or Cancelled, Return/Refund). Seller: New → Accepted → Packed → Ready for Pickup. Shipment: Ready for Pickup → Assigned → Picked Up → At Hub → Out for Delivery → Delivered (or Failed Delivery → Return to Sender → Returned to Sender). No status can be skipped or moved backwards except by a logged Logistics override.
A15: A11 | B15: Order completion and return window | C15: The buyer clicks Order Received, or the order completes automatically 7 days (168 hours) after Delivered. A return or refund can be requested only after Delivered, within those 7 days and before the order is Completed.
A16: A12 | B16: Reviews | C16: A review is allowed only for Completed orders, within 30 days of completion, one review per item. Stars (1–5) are required; text is optional, up to 500 characters; up to 5 photos. It can be edited once within the 30 days. The seller can post one reply per review and edit it; the seller cannot delete or hide a buyer's review.
... A41: A37 | B41: Duplicate submissions | C41: Every create or submit action (Publish, Place Order, Pay, Request Payout, Accept job, Remit, Confirm) is idempotent: double-clicking, pressing Enter twice, refreshing or pressing Back and resubmitting never creates a second record or a second charge.

Sheet Test Data
A1: Test data
A2: Shared by all five module workbooks. All people, stores, numbers and addresses are fictional. Seed these products, vouchers and rates before testing, or replace them with your own and update the Test Data column on the module sheets.
A4: Accounts (created in the Account Creation test set)
A5: Ref | B5: Role | C5: Name / store | D5: Login email | E5: Password | F5: Status / notes
A6: Buyer 1 | B6: Buyer | C6: Juan Miguel Dela Cruz | D6: juanmiguel.delacruz@example.com | E6: Mamimili@2026 | F6: Active. Main buyer.
A7: Buyer 2 | B7: Buyer | C7: Ana Marie Reyes | D7: anamarie.reyes@example.com | E7: Suki#2026Ana | F7: Active. Second buyer for concurrency and access tests.
A8: Seller 1 | B8: Seller | C8: Maria Clara Handicrafts (Maria Clara Santos) | D8: mariaclara.santos@example.com | E8: Tindahan@2026 | F8: Approved. Pickup: Commonwealth, Quezon City (NCR). Main seller.
A9: Seller 2 | B9: Seller | C9: RV Gadget Hub (Roberto Villanueva) | D9: roberto.villanueva@example.com | E9: Gadget#Hub26 | F9: Approved. Pickup: Lahug, Cebu City (Visayas).
A10: Seller 3 | B10: Seller | C10: Tindahan ni Lola (test) | D10: seller.test01@example.com | E10: Tindahan@2026 | F10: Pending Approval. For the unverified-seller cases.
A11: Logistics 1 | B11: Logistics | C11: Bilis Hatid Express Inc. (Carlos Antonio Mendoza) | D11: operations@bilishatid.example.com | E11: Hatid@2026 | F11: Approved. Serves NCR and CALABARZON. Main logistics account.
A12: Logistics 2 | B12: Logistics | C12: Agila Cargo Movers Corp. (Liza Mae Fernandez) | D12: admin@agilacargo.example.com | E12: Agila#Cargo26 | F12: Approved. Serves Davao. Used for cross-company access tests.
A13: Rider 1 | B13: Rider | C13: Pedro Jose Garcia (Motorcycle, 123ABC) | D13: pedrojose.garcia@example.com | E13: Rider@2026 | F13: Active, under Logistics 1. Main rider.
A14: Rider 2 | B14: Rider | C14: Mark Anthony Bautista (Van, NBC1234) | D14: markanthony.bautista@example.com | E14: Hatid#Mark26 | F14: Active, under Logistics 1. Second rider for concurrency tests.
A15: Rider 3 | B15: Rider | C15: Ramon Cruz (Motorcycle, 456DEF) | D15: rider.test01@example.com | E15: Rider@2026 | F15: Suspended by Logistics 1. For blocked-rider cases.
A16: Admin | B16: Admin | C16: Seeded admin | D16: Use the admin account already seeded in your system | F16: Creates platform vouchers PLAT100 and FREESHIP.
A18: Buyer addresses
A19: Ref | B19: Owner | C19: Label | D19: Address | E19: Recipient / phone | F19: Notes
A20: ADDR-1 | B20: Buyer 1 | C20: Home (default) | D20: 45 Kalayaan Ave., Brgy. Central, Quezon City, Metro Manila, NCR 1100 | E20: Juan Miguel Dela Cruz / 09171234567 | F20: Zone NCR
A21: ADDR-2 | B21: Buyer 1 | C21: Office | D21: 12F Pacific Tower, 6750 Ayala Ave., Brgy. San Lorenzo, Makati City, Metro Manila, NCR 1223 | E21: Juan Miguel Dela Cruz / 09171234567 | F21: Zone NCR
A22: ADDR-3 | B22: Buyer 2 | C22: Home (default) | D22: 78 Osmeña Blvd., Brgy. Capitol Site, Cebu City, Cebu, Region VII 6000 | E22: Ana Marie Reyes / 09173456789 | F22: Zone Visayas
A23: ADDR-4 | B23: Buyer 1 | C23: Province | D23: Purok 2, Brgy. Raele, Itbayat, Batanes, Region II 3905 | E23: Juan Miguel Dela Cruz / 09171234567 | F23: Unserviceable area (no logistics zone covers it)
A25: Store categories (Seller 1)
A26: Ref | B26: Category | C26: Parent | D26: Visible | E26: Products | F26: Notes
A27: CAT-1 | B27: Bags | D27: Yes | E27: P-01
A28: CAT-2 | B28: Home Decor | D28: Yes | F28: Parent category
A29: CAT-3 | B29: Lamps | C29: Home Decor | D29: Yes | E29: P-03 | F29: Subcategory (level 2)
A30: CAT-4 | B30: Baskets | C30: Home Decor | D30: Yes | E30: P-02 | F30: Subcategory (level 2)
A31: CAT-5 | B31: Kitchen & Dining | D31: Yes | E31: P-04
A33: Products
A34: Ref | B34: Seller | C34: Product | D34: Price / variants | E34: Stock | F34: Weight and size / other
A35: P-01 | B35: Seller 1 | C35: Abaca Woven Tote Bag | D35: Color: Natural, Black × Size: S ₱199, M ₱249, L ₱299 (6 variants). SKU MCH-TOTE-<COLOR>-<SIZE> | E35: Natural-S 10, Natural-M 8, Natural-L 5, Black-S 10, Black-M 0, Black-L 3 | F35: 0.4 kg; 40 × 35 × 5 cm. Platform category: Women's Bags
A36: P-02 | B36: Seller 1 | C36: Rattan Fruit Basket | D36: ₱450.00 (no variants) | E36: 20 | F36: 0.8 kg; 30 × 30 × 15 cm. Platform category: Home & Living
A37: P-03 | B37: Seller 1 | C37: Capiz Shell Lamp | D37: ₱1,250.00 | E37: 1 (for the oversell case) | F37: 1.5 kg; 30 × 30 × 40 cm
A38: P-04 | B38: Seller 1 | C38: Banig Placemat Set of 4 | D38: ₱350.00 | E38: 0 (out of stock) | F38: 0.5 kg
A39: P-05 | B39: Seller 2 | C39: USB-C Fast Charger 20W | D39: ₱399.00 | E39: 50 | F39: 0.2 kg; 10 × 8 × 5 cm
A40: P-06 | B40: Seller 2 | C40: Wireless Earbuds X2 | D40: Color: Black, White; ₱1,499.00 each | E40: Black 10, White 10 | F40: 0.3 kg
A41: P-07 | B41: Seller 2 | C41: Power Bank 10000mAh | D41: ₱899.00; per-buyer purchase limit 2 | E41: 5 | F41: 0.4 kg
A43: Vouchers
A44: Code | B44: Owner / funded by | C44: Type | D44: Rule | E44: Limits / validity | F44: Display
A45: MCH50 | B45: Seller 1 / seller | C45: Fixed ₱50 off | D45: Min spend ₱300; all Seller 1 products | E45: 100 total, 1 per buyer; valid this month | F45: Claimable
...

Sheet L1 Dashboard
A1: Test Case ID | B1: Module | C1: Test Scenario | D1: Technique | E1: Priority | F1: Preconditions | G1: Test Steps | H1: Test Data | I1: Expected Result | J1: Assumption Ref | K1: Actual Result | L1: Status | M1: Remarks
A2: LOG-DASH-001 | B2: Operations Dashboard | C2: Counts match the records | D2: Use Case Testing | E2: High | F2: Logged in as Logistics 1. Shipments exist in Pending (Ready for Pickup/Unassigned), In Transit, Delivered and Failed. | G2: 1. Open the dashboard and note each count. 2. Open the shipment list filtered by each status and count the rows. | I2: Each dashboard count equals the filtered list exactly. | L2: Not Run
A3: LOG-DASH-002 | B3: Operations Dashboard | C3: Counts update after a status change | D3: State Transition | E3: Medium | F3: Logged in as Logistics 1. | G3: 1. Note In Transit and Delivered. 2. Rider 1 marks a parcel Delivered. 3. Refresh the dashboard. | I3: In Transit −1 and Delivered +1; other counts unchanged. | L3: Not Run
A4: LOG-DASH-003 | B4: Operations Dashboard | C4: Date filter | D4: Boundary Value Analysis | E4: Medium | F4: Logged in as Logistics 1. | G4: 1. Filter today and a range that starts and ends on a shipment's date. | I4: Shipments on the start and end dates are counted. | L4: Not Run
A5: LOG-DASH-004 | B5: Operations Dashboard | C5: Only own company's data | D5: Error Guessing | E5: High | F5: Logged in as Logistics 1. Logistics 2 has shipments. | G5: 1. Compare the dashboard with Logistics 2's shipment count. | I5: No Logistics 2 shipment is counted or listed. | J5: A22 | L5: Not Run

Sheet L2 Rider Mgmt
A1: Test Case ID | B1: Module | C1: Test Scenario | D1: Technique | E1: Priority | F1: Preconditions | G1: Test Steps | H1: Test Data | I1: Expected Result | J1: Assumption Ref | K1: Actual Result | L1: Status | M1: Remarks
A2: LOG-RIDER-001 | B2: Rider Management | C2: Approve a rider | D2: State Transition | E2: High | F2: Logged in as Logistics 1. A rider (rider.test02@example.com) is pending verification. | G2: 1. Open the record and both documents. 2. Click Approve. 3. Log in as that rider and go Online. | I2: Status Active; the rider can go Online. The approval is in the audit log. | J2: A14, A35 | L2: Not Run
A3: LOG-RIDER-002 | B3: Rider Management | C3: Reject a rider with a reason | D3: State Transition | E3: Medium | F3: Logged in as Logistics 1. | G3: 1. Click Reject with an empty reason. 2. Reject with the test reason. | H3: Reason: OR/CR photo is unreadable, please re-upload. | I3: The empty reason is blocked. After rejection the rider is notified with the exact reason and cannot go Online. | J3: A25 | L3: Not Run
A4: LOG-RIDER-003 | B4: Rider Management | C4: Suspend a rider with active jobs | D4: State Transition | E4: High | F4: Logged in as Logistics 1. Rider 2 is Online with 1 Assigned (not picked up) job and 1 Picked Up job. | G4: 1. Suspend Rider 2 with a reason. 2. Check Rider 2's app, the Unassigned queue and the audit log. | H4: Reason: Repeated late deliveries this week. | I4: Rider 2 goes Offline and cannot go Online. The Assigned job moves to the Unassigned queue; the Picked Up job stays with Rider 2. The suspension is logged. | J4: A34, A35 | L4: Not Run
A5: LOG-RIDER-004 | B5: Rider Management | C5: Suspend without a reason | D5: Equivalence Partitioning | E5: Medium | F5: Logged in as Logistics 1. | G5: 1. Click Suspend with an empty or 9-character reason. | I5: Blocked; rider unchanged. | J5: A25 | L5: Not Run
A6: LOG-RIDER-005 | B6: Rider Management | C6: Reactivate a rider | D6: State Transition | E6: Medium | F6: Rider 3 is Suspended. | G6: 1. Reactivate Rider 3. 2. Log in as Rider 3 and go Online. | I6: Rider 3 is Active and can go Online. | J6: A35 | L6: Not Run
A7: LOG-RIDER-006 | B7: Rider Management | C7: Rider status and workload | D7: Use Case Testing | E7: Medium | F7: Logged in as Logistics 1. | G7: 1. Open the rider list. | I7: Each rider shows Online/Offline, active jobs (0–3) and today's completed deliveries, matching their apps. | L7: Not Run
A8: LOG-RIDER-007 | B8: Rider Management | C8: Cannot manage another company's rider | D8: Error Guessing | E8: High | F8: Logged in as Logistics 2. | G8: 1. Open Rider 1's record by URL or request. 2. Send a suspend request for Rider 1. | I8: Both are denied. Rider 1 is unchanged. | J8: A22 | L8: Not Run

Sheet L3 Dispatch
A1: Test Case ID | B1: Module | C1: Test Scenario | D1: Technique | E1: Priority | F1: Preconditions | G1: Test Steps | H1: Test Data | I1: Expected Result | J1: Assumption Ref | K1: Actual Result | L1: Status | M1: Remarks
A2: LOG-DISP-001 | B2: Dispatch & Assignment | C2: Auto-assign to the nearest eligible rider | D2: Use Case Testing | E2: High | F2: Logged in as Logistics 1. Rider 1 (near Seller 1) and Rider 2 (farther) are Online with 0 jobs. A parcel is Ready for Pickup. | G2: 1. Run auto-assign. | I2: The offer goes to Rider 1 first. | J2: A34 | L2: Not Run
A3: LOG-DISP-002 | B3: Dispatch & Assignment | C3: Manual assign | D3: Use Case Testing | E3: High | F3: Logged in as Logistics 1. | G3: 1. Assign the parcel to Rider 2 manually. | I3: Rider 2 receives it; status Assigned; the buyer timeline shows the assignment. | J3: A10 | L3: Not Run
A4: LOG-DISP-003 | B4: Dispatch & Assignment | C4: Offline or suspended rider not assignable | D4: Equivalence Partitioning | E4: High | F4: Logged in as Logistics 1. Rider 1 is Offline; Rider 3 is Suspended. | G4: 1. Open Manual Assign. 2. Send an assign request for Rider 3 directly. | I4: Neither rider is listed. The direct request is rejected. | J4: A14 | L4: Not Run
A5: LOG-DISP-004 | B5: Dispatch & Assignment | C5: Rider at the job limit | D5: Boundary Value Analysis | E5: Medium | F5: Logged in as Logistics 1. Rider 2 has 3 active jobs. | G5: 1. Try to assign a 4th. | I5: Blocked with a limit message. | J5: A14 | L5: Not Run
A6: LOG-DISP-005 | B6: Dispatch & Assignment | C6: Reassign before pickup | D6: State Transition | E6: High | F6: Logged in as Logistics 1. Parcel Assigned to Rider 1. | G6: 1. Reassign to Rider 2. | I6: Rider 1 loses the job immediately; Rider 2 has it. The timeline shows both events. | J6: A34 | L6: Not Run
A7: LOG-DISP-006 | B7: Dispatch & Assignment | C7: No reassign after pickup | D7: State Transition | E7: High | F7: Logged in as Logistics 1. Parcel Picked Up by Rider 1. | G7: 1. Look for Reassign. 2. Send the request directly. | I7: Not available; the request is rejected. | J7: A34 | L7: Not Run
A8: LOG-DISP-007 | B8: Dispatch & Assignment | C8: Bulk assignment over the limit | D8: Boundary Value Analysis | E8: Medium | F8: Logged in as Logistics 1. 5 parcels are Ready for Pickup; Rider 2 has 0 jobs. | G8: 1. Select all 5 and assign to Rider 2. | I8: 3 are assigned and 2 are reported as skipped because of the 3-job limit. The 2 stay Unassigned. | J8: A14 | L8: Not Run
A9: LOG-DISP-008 | B9: Dispatch & Assignment | C9: Assign a parcel that is not ready | D9: Error Guessing | E9: Medium | F9: Logged in as Logistics 1. An order is only Packed. | G9: 1. Look for it in the dispatch queue. 2. Send an assign request directly. | I9: It is not in the queue and the request is rejected. | J9: A10 | L9: Not Run

Sheet L4 Hub Ops
A1: Test Case ID | B1: Module | C1: Test Scenario | D1: Technique | E1: Priority | F1: Preconditions | G1: Test Steps | H1: Test Data | I1: Expected Result | J1: Assumption Ref | K1: Actual Result | L1: Status | M1: Remarks
A2: LOG-HUB-001 | B2: Hub & Warehouse Operations | C2: Inbound receiving by scan | D2: State Transition | E2: High | F2: Logged in as Logistics 1. Rider 1 brings a Picked Up parcel to the hub. | G2: 1. Scan it at Inbound. 2. Check Buyer 1's timeline. | I2: Status At Hub with the scan time, in Logistics and Buyer views. | J2: A10 | L2: Not Run
A3: LOG-HUB-002 | B3: Hub & Warehouse Operations | C3: Sort by zone | D3: Use Case Testing | E3: Medium | F3: Logged in as Logistics 1. | G3: 1. Sort the parcel. | H3: ADDR-1 → NCR zone | I3: The parcel is placed in the NCR zone list only. | L3: Not Run
A4: LOG-HUB-003 | B4: Hub & Warehouse Operations | C4: Outbound dispatch | D4: State Transition | E4: High | F4: Logged in as Logistics 1. | G4: 1. Scan at Outbound and assign Rider 1. 2. Rider 1 marks Out for Delivery. | I4: Status Out for Delivery; the delivery OTP appears in Buyer 1's order. | J4: A10, A32 | L4: Not Run
A5: LOG-HUB-004 | B5: Hub & Warehouse Operations | C5: Duplicate scan | D5: Error Guessing | E5: Medium | F5: Logged in as Logistics 1. | G5: 1. Scan the same parcel twice at Inbound. | I5: The second scan warns 'already received'. Only one At Hub event exists. | J5: A37 | L5: Not Run
A6: LOG-HUB-005 | B6: Hub & Warehouse Operations | C6: Parcel not in the system | D6: Equivalence Partitioning | E6: High | F6: Logged in as Logistics 1. | G6: 1. Scan an unknown tracking number. | H6: TRK-0000000 | I6: Rejected with 'not found'. No record is created. | L6: Not Run
A7: LOG-HUB-006 | B7: Hub & Warehouse Operations | C7: Out-of-order scan | D7: State Transition | E7: Medium | F7: Logged in as Logistics 1. | G7: 1. Scan a parcel at Outbound before Inbound. | I7: Blocked; status unchanged. | J7: A10 | L7: Not Run
A8: LOG-HUB-007 | B8: Hub & Warehouse Operations | C8: Another company's parcel | D8: Error Guessing | E8: Medium | F8: Logged in as Logistics 1. | G8: 1. Scan a Logistics 2 tracking number. | I8: Rejected; Logistics 2's shipment unchanged. | J8: A22 | L8: Not Run

Sheet L5 Tracking & Exceptions
A1: Test Case ID | B1: Module | C1: Test Scenario | D1: Technique | E1: Priority | F1: Preconditions | G1: Test Steps | H1: Test Data | I1: Expected Result | J1: Assumption Ref | K1: Actual Result | L1: Status | M1: Remarks
A2: LOG-TRK-001 | B2: Shipment Tracking & Exceptions | C2: Search by tracking number, order ID or buyer | D2: Equivalence Partitioning | E2: High | F2: Logged in as Logistics 1. | G2: 1. Search by each value. 2. Search an unknown value and an injection string. | H2: Tracking number; order ID; Juan Miguel Dela Cruz; ' OR '1'='1 | I2: Each valid search returns exactly the right shipment. Unknown values return no results with no error. | L2: Not Run
A3: LOG-TRK-002 | B3: Shipment Tracking & Exceptions | C3: Manual override needs a reason | D3: Equivalence Partitioning | E3: High | F3: Logged in as Logistics 1. A parcel is Out for Delivery. | G3: 1. Override to Delivered with an empty reason. 2. Override with the test reason. | H3: Reason: Rider app offline, delivery confirmed by phone. | I3: The empty reason is blocked. With the reason, status becomes Delivered. | J3: A10, A25 | L3: Not Run
A4: LOG-TRK-003 | B4: Shipment Tracking & Exceptions | C4: Override leaves an audit log | D4: Use Case Testing | E4: High | F4: The previous case was run. | G4: 1. Open the audit log. 2. Look for Edit or Delete on the entry. | I4: The entry shows user, date and time, Out for Delivery → Delivered and the reason. There is no Edit or Delete. | J4: A35 | L4: Not Run
A5: LOG-TRK-004 | B5: Shipment Tracking & Exceptions | C5: Mark a parcel Lost | D5: State Transition | E5: Medium | F5: Logged in as Logistics 1. | G5: 1. Mark a parcel Lost with a reason. | I5: Status Lost; Buyer 1 and Seller 1 are notified; the refund or claim process starts. | J5: A23 | L5: Not Run
A6: LOG-TRK-005 | B6: Shipment Tracking & Exceptions | C6: Mark a parcel Damaged with a photo | D6: State Transition | E6: Medium | F6: Logged in as Logistics 1. | G6: 1. Mark Damaged without a photo, then with one. | H6: pod_photo.jpg | I6: Blocked without a photo; with it, status and photo are saved and both parties notified. | J6: A16 | L6: Not Run

Sheet L6 Returns (RTS)
A1: Test Case ID | B1: Module | C1: Test Scenario | D1: Technique | E1: Priority | F1: Preconditions | G1: Test Steps | H1: Test Data | I1: Expected Result | J1: Assumption Ref | K1: Actual Result | L1: Status | M1: Remarks
A2: LOG-RTS-001 | B2: Returns (Return-to-Sender) | C2: RTS queue after 3 failed attempts | D2: State Transition | E2: High | F2: A parcel failed 3 times. | G2: 1. Open the RTS queue. | I2: The parcel is listed with status Return to Sender and all 3 failure reasons. | J2: A13 | L2: Not Run
A3: LOG-RTS-002 | B3: Returns (Return-to-Sender) | C3: Deliver back to the seller | D3: State Transition | E3: High | F3: Logged in as Logistics 1. | G3: 1. Assign the RTS parcel to Rider 1. 2. Rider 1 delivers it to Seller 1. 3. Check all three views. | I3: Status Returned to Sender. Buyer: order Cancelled (failed delivery). Seller: Returned, awaiting confirmation. | J3: A10 | L3: Not Run
A4: LOG-RTS-003 | B4: Returns (Return-to-Sender) | C4: Stock restored only when the seller confirms | D4: State Transition | E4: High | F4: The RTS parcel (1 × P-02) is Returned to Sender; stock is 19. | G4: 1. Check stock. 2. Seller 1 confirms receipt. 3. Check stock again. | I4: Stock stays 19 until confirmation, then becomes 20. | J4: A3 | L4: Not Run
A5: LOG-RTS-004 | B5: Returns (Return-to-Sender) | C5: Prepaid RTS refund and no earnings | D5: State Transition | E5: Medium | F5: The RTS order was prepaid. | G5: 1. Complete RTS. 2. Check Buyer 1's refund and Seller 1's earnings. | I5: Buyer 1's refund for the full amount is started. Seller 1 has no earnings for the order. | J5: A15 | L5: Not Run

Sheet L7 Zones & Rates
A1: Test Case ID | B1: Module | C1: Test Scenario | D1: Technique | E1: Priority | F1: Preconditions | G1: Test Steps | H1: Test Data | I1: Expected Result | J1: Assumption Ref | K1: Actual Result | L1: Status | M1: Remarks
A2: LOG-RATE-001 | B2: Delivery Zones & Shipping Rates | C2: Rate change shows at checkout | D2: State Transition | E2: High | F2: Logged in as Logistics 1. Buyer 1 has an order placed at the old rate. | G2: 1. Change Within NCR first kg from ₱50 to ₱55. 2. As Buyer 1, start a new checkout of P-02 to ADDR-1. 3. Open the earlier order. | I2: The new checkout shows ₱55.00. The earlier order still shows ₱50.00. The change is in the audit log. | J2: A20, A35 | L2: Not Run
A3: LOG-RATE-002 | B3: Delivery Zones & Shipping Rates | C3: Invalid rate values | D3: Boundary Value Analysis | E3: Medium | F3: Logged in as Logistics 1. | G3: 1. Enter each value and save. | H3: -1 (reject) 0 (reject) 0.01 (accept) abc (reject) | I3: Only 0.01 saves. | L3: Not Run
A4: LOG-RATE-003 | B4: Delivery Zones & Shipping Rates | C4: Unserviceable area blocked | D4: Equivalence Partitioning | E4: High | F4: ADDR-4 is outside every zone. | G4: 1. As Buyer 1, check out to ADDR-4. | I4: Place Order is blocked with a not-serviceable message. | L4: Not Run
A5: LOG-RATE-004 | B5: Delivery Zones & Shipping Rates | C5: Add a zone | D5: State Transition | E5: Medium | F5: Logged in as Logistics 1. | G5: 1. Add a zone covering Batanes with a rate. 2. As Buyer 1, check out to ADDR-4 again. | I5: Checkout now works and uses the new rate. | J5: A20 | L5: Not Run

Sheet L8 COD & Reports
A1: Test Case ID | B1: Module | C1: Test Scenario | D1: Technique | E1: Priority | F1: Preconditions | G1: Test Steps | H1: Test Data | I1: Expected Result | J1: Assumption Ref | K1: Actual Result | L1: Status | M1: Remarks
A2: LOG-COD-001 | B2: COD Reconciliation & Reports | C2: Remittance matches COD collected | D2: Use Case Testing | E2: High | F2: Rider 1 collected ₱1,800.00 and remitted ₱1,800.00. | G2: 1. Open reconciliation for today. | I2: Collected ₱1,800.00, remitted ₱1,800.00, difference ₱0.00, with both orders listed. | J2: A24 | L2: Not Run
A3: LOG-COD-002 | B3: COD Reconciliation & Reports | C3: Short remittance flagged | D3: Equivalence Partitioning | E3: High | F3: Rider 1 remitted ₱1,750.00. | G3: 1. Open reconciliation. | I3: Difference −₱50.00 is highlighted as a shortfall. | J3: A24 | L3: Not Run
A4: LOG-COD-003 | B4: COD Reconciliation & Reports | C4: Confirm remittance | D4: State Transition | E4: Medium | F4: Logged in as Logistics 1. | G4: 1. Confirm the remittance. 2. Check Rider 1's balance and the audit log. | I4: Rider 1's balance updates; the confirmation is logged. | J4: A24, A35 | L4: Not Run
A5: LOG-COD-004 | B5: COD Reconciliation & Reports | C5: Export reports | D5: Use Case Testing | E5: Medium | F5: Logged in as Logistics 1. | G5: 1. Export deliveries and COD for a date range as CSV and as XLSX. 2. Open both files. | I5: Both files download and open. Rows and totals equal the screen for the same filter. | J5: A36 | L5: Not Run
A6: LOG-COD-005 | B6: COD Reconciliation & Reports | C6: Export with no data | D6: Error Guessing | E6: Low | F6: Logged in as Logistics 1. | G6: 1. Export a range with no records. | I6: A file with headers only, or a 'no data' message. No error. | J6: A36 | L6: Not Run
