Workbook

Sheet Summary
A1: Black-Box Test Cases: Account Creation
A2: Multi-role e-commerce system (Buyer, Seller, Logistics, Rider)
A4: Test run details
A5: System under test | B5: Loved-IT multi-vendor marketplace (loved-it.shop): React web app and Laravel API
A6: Version / build | B6: Branch king/courier-companies, commit 335f7c5 (17 Oct 2026)
A7: Test environment (browser, device) | B7: Microsoft Edge (Chromium) 1366×900 on Windows 11, driven by Puppeteer; an isolated copy of the system (own database, file storage and mail log) on 127.0.0.1, with the same PHP settings as the live server
A8: Tester | B8: Automated black-box run by Claude Code (AI assistant) for the Basta Corp. team
A9: Date tested | B9: 10/17/2026 – 10/18/2026
A11: Results by role
A12: Role (sheet) | B12: Total test cases | C12: Pass | D12: Fail | E12: Blocked | F12: Not Run | G12: Pass rate (Pass / Total)
A13: Buyer | B13: =COUNTA(#REF!) -> #REF! | C13: =COUNTIF(#REF!,"Pass") -> #REF! | D13: =COUNTIF(#REF!,"Fail") -> #REF! | E13: =COUNTIF(#REF!,"Blocked") -> #REF! | F13: =COUNTIF(#REF!,"Not Run") -> #REF! | G13: =IF(B13=0,0,C13/B13) -> #REF!
A14: Seller | B14: =COUNTA(#REF!) -> #REF! | C14: =COUNTIF(#REF!,"Pass") -> #REF! | D14: =COUNTIF(#REF!,"Fail") -> #REF! | E14: =COUNTIF(#REF!,"Blocked") -> #REF! | F14: =COUNTIF(#REF!,"Not Run") -> #REF! | G14: =IF(B14=0,0,C14/B14) -> #REF!
A15: Logistics | B15: =COUNTA(Logistics!$A$2:$A$200) -> 44 | C15: =COUNTIF(Logistics!$L$2:$L$200,"Pass") -> 0 | D15: =COUNTIF(Logistics!$L$2:$L$200,"Fail") -> 0 | E15: =COUNTIF(Logistics!$L$2:$L$200,"Blocked") -> 0 | F15: =COUNTIF(Logistics!$L$2:$L$200,"Not Run") -> 44 | G15: =IF(B15=0,0,C15/B15) -> 0
A16: Rider | B16: =COUNTA(#REF!) -> #REF! | C16: =COUNTIF(#REF!,"Pass") -> #REF! | D16: =COUNTIF(#REF!,"Fail") -> #REF! | E16: =COUNTIF(#REF!,"Blocked") -> #REF! | F16: =COUNTIF(#REF!,"Not Run") -> #REF! | G16: =IF(B16=0,0,C16/B16) -> #REF!
A17: Total | B17: =SUM(B13:B16) -> #REF! | C17: =SUM(C13:C16) -> #REF! | D17: =SUM(D13:D16) -> #REF! | E17: =SUM(E13:E16) -> #REF! | F17: =SUM(F13:F16) -> #REF! | G17: =IF(B17=0,0,C17/B17) -> #REF!
A19: How to use this workbook
A20: 1. Read the Assumptions sheet first. The rules are modeled on Philippine marketplaces, so adjust any case whose rule differs from your system.
A21: 2. The Test Data sheet lists every form field with two ready-made accounts per role. The Test Files sheet lists the upload files to prepare. All people, companies and numbers are fictional.
A22: 3. Emails use example.com, so nothing is delivered to a real inbox. Read OTP and activation emails from a mail catcher such as Mailtrap, or from your application's mail log.
A23: 4. On each role sheet, run the Test Steps with the Test Data and compare what happens with the Expected Result. Use a spare email and mobile number from the Test Data sheet whenever a value marked (accept) creates another account.
A24: 5. Dates of birth and license expiry dates in the boundary cases are calculated from today's date, so they are always correct on the day you test.
A25: 6. Fill in only the yellow cells: Actual Result, Status and Remarks. Pick the Status from the dropdown (Pass, Fail, Blocked, Not Run).
A26: 7. Pass = actual matches expected. Fail = it does not (describe what happened and add a screenshot or bug number in Remarks). Blocked = the case could not be run, for example because an earlier case failed.
A27: 8. The Results by role table above updates automatically from the Status column.
A29: Example of a filled-in row (illustration only, not a real result)
A30: Test Case ID | B30: Test Scenario | C30: Expected Result | D30: Actual Result | E30: Status | F30: Remarks
A31: TC-BUY-010 | B31: Email that is already registered | C31: Registration is blocked. A message says the email is already in use. No account is created. | D31: No message was shown. A second account was created with juanmiguel.delacruz@example.com. | E31: Fail | F31: Bug #012. Screenshot: buy-010.png
A34: Black-box techniques used
A35: Equivalence Partitioning | B35: Inputs are grouped into valid and invalid classes, and one value from each class is tested.
A36: Boundary Value Analysis | B36: Values at and just beyond a limit are tested, for example 7 and 8 characters for a minimum of 8.
A37: Decision Table | B37: Combinations of conditions are tested, for example each missing password character type.
A38: State Transition | B38: Changes in account status are tested, for example Unverified to Active or Pending Approval to Approved.
A39: Use Case Testing | B39: A complete user flow is tested from start to finish with valid data.
A40: Error Guessing | B40: Likely mistakes are tested based on experience, for example double-clicking Register or pasting another role's URL.

Sheet Test Data
A1: Test data and input details
A2: Every form field per role, with its rule and two complete sets of valid data. Account 1 is the main account in the test cases. Account 2 is for cases that need a second account. All people, companies, numbers and addresses are fictional.
A4: Buyer: Self-registration
A5: Role | B5: Field | C5: Required | D5: Input type | E5: Format / rule | F5: Account 1 (valid) | G5: Account 2 (valid)
A6: Buyer | B6: First Name | C6: Yes | D6: Text | E6: 2 to 50 characters; letters, spaces, hyphen, apostrophe, period | F6: Juan Miguel | G6: Ana Marie
A7: Buyer | B7: Last Name | C7: Yes | D7: Text | E7: 2 to 50 characters; letters, spaces, hyphen, apostrophe, period | F7: Dela Cruz | G7: Reyes
A8: Buyer | B8: Email | C8: Yes | D8: Email | E8: Valid email format; unique | F8: juanmiguel.delacruz@example.com | G8: anamarie.reyes@example.com
A9: Buyer | B9: Mobile Number | C9: Yes | D9: Text | E9: 09XXXXXXXXX or +639XXXXXXXXX; unique | F9: 09171234567 | G9: 09173456789
A10: Buyer | B10: Date of Birth | C10: Yes | D10: Date picker | E10: At least 18 years old | F10: 05/14/1998 | G10: 11/02/2001
A11: Buyer | B11: Password | C11: Yes | D11: Password | E11: Min 8 characters; uppercase, lowercase, number, special character | F11: Mamimili@2026 | G11: Suki#2026Ana
A12: Buyer | B12: Confirm Password | C12: Yes | D12: Password | E12: Must match Password | F12: Mamimili@2026 | G12: Suki#2026Ana
A13: Buyer | B13: Terms and Privacy Policy | C13: Yes | D13: Checkbox | E13: Must be ticked | F13: Ticked | G13: Ticked
A15: Seller: Self-registration, then admin approval
A16: Role | B16: Field | C16: Required | D16: Input type | E16: Format / rule | F16: Account 1 (valid) | G16: Account 2 (valid)
A17: Seller | B17: First Name | C17: Yes | D17: Text | E17: 2 to 50 characters; letters, spaces, hyphen, apostrophe, period | F17: Maria Clara | G17: Roberto
A18: Seller | B18: Last Name | C18: Yes | D18: Text | E18: 2 to 50 characters; letters, spaces, hyphen, apostrophe, period | F18: Santos | G18: Villanueva
A19: Seller | B19: Email | C19: Yes | D19: Email | E19: Valid email format; unique | F19: mariaclara.santos@example.com | G19: roberto.villanueva@example.com
A20: Seller | B20: Mobile Number | C20: Yes | D20: Text | E20: 09XXXXXXXXX or +639XXXXXXXXX; unique | F20: 09189876543 | G20: 09194567890
A21: Seller | B21: Shop Name | C21: Yes | D21: Text | E21: 3 to 30 characters; unique | F21: Maria Clara Handicrafts | G21: RV Gadget Hub
A22: Seller | B22: Shop Category | C22: Yes | D22: Dropdown | E22: One main category | F22: Home & Living | G22: Mobiles & Gadgets
A23: Seller | B23: Seller Type | C23: Yes | D23: Dropdown | E23: Individual, Sole Proprietorship or Corporation | F23: Sole Proprietorship | G23: Corporation
A24: Seller | B24: TIN | C24: Yes | D24: Text | E24: 000-000-000-000 (12 digits); unique | F24: 123-456-789-000 | G24: 456-789-012-000
A25: Seller | B25: Region | C25: Yes | D25: Dropdown | E25: Philippine regions | F25: National Capital Region (NCR) | G25: Region VII (Central Visayas)
A26: Seller | B26: Province | C26: Yes | D26: Dropdown | E26: Filtered by Region | F26: Metro Manila | G26: Cebu
A27: Seller | B27: City / Municipality | C27: Yes | D27: Dropdown | E27: Filtered by Province | F27: Quezon City | G27: Cebu City
... A37: Seller | B37: Terms and Privacy Policy | C37: Yes | D37: Checkbox | E37: Must be ticked | F37: Ticked | G37: Ticked
A39: Logistics: Self-registration, then admin approval
A40: Role | B40: Field | C40: Required | D40: Input type | E40: Format / rule | F40: Account 1 (valid) | G40: Account 2 (valid)
A41: Logistics | B41: Company Name | C41: Yes | D41: Text | E41: Unique | F41: Bilis Hatid Express Inc. | G41: Agila Cargo Movers Corp.
A42: Logistics | B42: SEC Registration No. | C42: Yes | D42: Text | E42: 2 letters followed by 9 digits; unique | F42: CS202012345 | G42: CS201998765
A43: Logistics | B43: TIN | C43: Yes | D43: Text | E43: 000-000-000-000 (12 digits); unique | F43: 234-567-890-000 | G43: 567-890-123-000
A44: Logistics | B44: Region | C44: Yes | D44: Dropdown | E44: Philippine regions | F44: National Capital Region (NCR) | G44: Region XI (Davao Region)
A45: Logistics | B45: Province | C45: Yes | D45: Dropdown | E45: Filtered by Region | F45: Metro Manila | G45: Davao del Sur
A46: Logistics | B46: City / Municipality | C46: Yes | D46: Dropdown | E46: Filtered by Province | F46: Pasig City | G46: Davao City
A47: Logistics | B47: Barangay | C47: Yes | D47: Dropdown | E47: Filtered by City / Municipality | F47: Kapitolyo | G47: Buhangin
A48: Logistics | B48: Street Address | C48: Yes | D48: Text | E48: House, unit or lot number and street | F48: Unit 5B, 88 West Capitol Drive | G48: Door 3, 210 Sampaguita St.
A49: Logistics | B49: Postal Code | C49: Yes | D49: Text | E49: Exactly 4 digits | F49: 1603 | G49: 8000
A50: Logistics | B50: Contact Person First Name | C50: Yes | D50: Text | E50: 2 to 50 characters; letters, spaces, hyphen, apostrophe, period | F50: Carlos Antonio | G50: Liza Mae
A51: Logistics | B51: Contact Person Last Name | C51: Yes | D51: Text | E51: 2 to 50 characters; letters, spaces, hyphen, apostrophe, period | F51: Mendoza | G51: Fernandez
... A62: Logistics | B62: Terms and Privacy Policy | C62: Yes | D62: Checkbox | E62: Must be ticked | F62: Ticked | G62: Ticked
...

Sheet Test Files
A1: Upload files to prepare
A2: Prepare these files before testing the document uploads. Use sample or blank documents, not anyone's real ID or certificate. The size limit is 5 MB, which is 5,120 KB or 5,242,880 bytes.
A4: File name | B4: Type | C4: Size | D4: Used for | E4: Expected result
A5: govt_id_front.jpg | B5: JPG | C5: 1.2 MB | D5: Valid government ID | E5: Accept
A6: govt_id_front.png | B6: PNG | C6: 2.4 MB | D6: Valid government ID in PNG | E6: Accept
A7: dti_certificate.pdf | B7: PDF | C7: 850 KB | D7: DTI Certificate of Business Name Registration | E7: Accept
A8: dti_certificate_clear.pdf | B8: PDF | C8: 1.0 MB | D8: Replacement document for the resubmit test (seller) | E8: Accept
A9: sec_certificate.pdf | B9: PDF | C9: 1.0 MB | D9: SEC Certificate of Registration | E9: Accept
A10: bir_2303.pdf | B10: PDF | C10: 1.1 MB | D10: BIR Certificate of Registration (Form 2303) | E10: Accept
A11: mayors_permit.pdf | B11: PDF | C11: 1.3 MB | D11: Mayor's / Business Permit | E11: Accept
A12: mayors_permit_2026.pdf | B12: PDF | C12: 1.2 MB | D12: Replacement document for the resubmit test (logistics) | E12: Accept
A13: drivers_license.jpg | B13: JPG | C13: 1.5 MB | D13: Rider's driver's license | E13: Accept
A14: drivers_license.png | B14: PNG | C14: 2.0 MB | D14: Rider's driver's license in PNG | E14: Accept
A15: drivers_license.pdf | B15: PDF | C15: 700 KB | D15: Rider's driver's license in PDF | E15: Accept
... A22: installer.exe | B22: EXE | C22: 2.1 MB | D22: Wrong file type (program) | E22: Reject

Sheet Assumptions
A1: Assumptions used in the test cases
A2: These rules are modeled on Philippine marketplaces, not taken from your actual system. Write your real rule in column D where it differs, then filter the Assumption Ref column on each role sheet to find the test cases to adjust.
A4: Ref | B4: Topic | C4: Assumed rule | D4: Your system's actual rule (fill in if different)
A5: A1 | B5: Form fields | C5: Each role's form has the fields listed on the Test Data sheet, modeled on Philippine marketplaces. Payout details (bank or e-wallet) are set up after approval, not during registration. | D5: Buyer: first, middle (optional) and last name, email, phone (+63 box), password and confirm password; then profile photo, birthday, sex, address (Province, City/Municipality, Barangay, optional street) and a government ID photo. No Terms and Privacy checkbox. Sellers, courier companies and riders first create this account, then apply with their own form (shop/company details and documents).
A6: A2 | B6: Name rule | C6: 2 to 50 characters. Letters (including ñ), spaces, hyphen, apostrophe and period only. | D6: Required, up to 50 characters. No minimum length and no character check: digits and symbols are accepted; ñ, hyphen and apostrophe work.
A7: A3 | B7: Email rule | C7: Must be a valid email format. Unique across all roles (one email = one account). Not case-sensitive. Leading and trailing spaces are removed. | D7: Checked by the browser and by the server, including a DNS check that the domain accepts mail (example.com is rejected because it has a null MX). Unique across all roles, not case-sensitive; spaces around it are removed. Max 100 characters.
A8: A4 | B8: Mobile number rule | C8: Philippine mobile number entered as 09XXXXXXXXX (11 digits) or +639XXXXXXXXX. Both forms are stored as the same number. Unique across all accounts. | D8: Typed after a fixed country-code dropdown (+63 by default). The box keeps digits only and at most 10 of them, with no message: 09XXXXXXXXX loses its last digit and +63 typed in the box is not recognised. Saved as +63 plus the digits; unique; no check that it is a mobile (09) number.
A9: A5 | B9: Password rule | C9: At least 8 characters with at least one uppercase letter, one lowercase letter, one number and one special character. Confirm Password must match. | D9: At least 8 characters with upper and lower case, a number and a symbol, and not found in known password leaks. Confirm Password must match. No show/hide icon.
A10: A6 | B10: Date of birth rule | C10: Buyers and riders must be at least 18 years old on the day of registration. A future date is not allowed. | D10: Buyers must be at least 18 on the day they register; the birthday picker does not allow future dates.
A11: A7 | B11: Address rule | C11: Region, Province, City/Municipality and Barangay are linked dropdowns: each list depends on the one before it. Postal Code is exactly 4 digits. | D11: Buyer and seller address: Province → City/Municipality → Barangay (PSGC lists; NCR is listed as "Metro Manila (NCR)"; no Region dropdown). The courier company form starts at Region. No postal code anywhere.
A12: A8 | B12: TIN rule | C12: 12 digits in the form 000-000-000-000 (9-digit TIN plus 3-digit branch code). Unique across seller and logistics accounts. | D12: No TIN is collected.
A13: A9 | B13: Email verification (OTP) | C13: A 6-digit numeric code is emailed after registration. It is valid for 5 minutes. Resending creates a new code and cancels the old one. An account cannot be used until it is verified. | D13: No email OTP. A welcome email is sent on registration; buyers are then verified by an admin who checks the government ID (pending → approved or rejected), and applicants get an email when an application is received and decided.
A14: A10 | B14: Document upload rule | C14: Accepted file types: JPG, PNG, PDF. Maximum size: 5 MB (5,120 KB) per file. | D14: JPG, PNG or PDF (profile photo also WebP), up to 5 MB in the app. However, the server's PHP settings allow only 2 MB per file and 8 MB per form, so files between 2 MB and 5 MB fail with "The … failed to upload."
A15: A11 | B15: Seller documents by seller type | C15: Individual: Government-issued ID. Sole Proprietorship: Government-issued ID, DTI Certificate and BIR Form 2303. Corporation: Government-issued ID of the representative, SEC Certificate and BIR Form 2303. | D15: No seller type. Every seller uploads a government ID (back too for some ID types), a selfie holding the ID, an LGU business permit and a DTI or SEC registration; an FDA LTO is optional.
... A20: A16 | B20: Role-based access | C20: Each role can open only its own pages. Opening another role's page is denied (error 403 or redirect). | D20: Pages of another role redirect (to the home page, the login page or the role's application page); the API answers 403.

Sheet Logistics
A1: Test Case ID | B1: Module | C1: Test Scenario | D1: Technique | E1: Priority | F1: Preconditions | G1: Test Steps | H1: Test Data | I1: Expected Result | J1: Assumption Ref | K1: Actual Result | L1: Status | M1: Remarks
A2: TC-LOG-001 | B2: Registration Form | C2: Register with all valid data | D2: Use Case Testing | E2: High | F2: The logistics registration page is open. The email, mobile number and other unique values in the test data are not yet registered. | G2: 1. Fill in every field with the test data. 2. Click Register. | H2: Company Name: Bilis Hatid Express Inc. SEC Registration No.: CS202012345 TIN: 234-567-890-000 Region: National Capital Region (NCR) Province: Metro Manila City / Municipality: Pasig City Barangay: Kapitolyo Street Address: Unit 5B, 88 West Capitol Drive Postal Code: 1603 Contact Person First Name: Carlos Antonio Contact Person Last Name: Mendoza Position: Operations Manager Email: operations@bilishatid.example.com Mobile Number: 09285551234 Service Areas: NCR; Region IV-A (CALABARZON) SEC Certificate (upload): sec_certificate.pdf (1.0 MB) BIR Form 2303 (upload): bir_2303.pdf (1.1 MB) Mayor's / Business Permit (upload): mayors_permit.pdf (1.3 MB) Valid ID of Authorized Representative (upload): govt_id_front.jpg (1.2 MB) Password: Hatid@2026 Confirm Password: Hatid@2026 Terms and Privacy Policy: Ticked | I2: The form is accepted with no validation errors. A success message is shown, a 6-digit OTP is sent to the email, and the email verification page opens. The account is saved with status Unverified. | J2: A1, A9, A12 | K2: Account step (Carlos Antonio Mendoza): accepted ("Account Submitted!"). Courier application (company name, short code BHE, description, contact number 09285551234, National Capital Region (NCR) > Metro Manila (NCR) > City of Pasig > Kapitolyo, street, mayors_permit.pdf): accepted with no errors; the page changed to "Under review – We're reviewing Bilis Hatid Express Inc.". The company is saved with status PENDING. Emails: Welcome to Loved-IT!; We received your courier company application. No OTP was sent and no email verification page opened. | L2: Fail | M2: Design difference (A9, A12): no email OTP; the application goes to admin review. The form has no SEC Registration No., TIN, Postal Code, Position, Service Areas, BIR 2303 or representative ID upload; it asks for a 2–6 character short code (BHE was used) and one business permit. The test-data addresses use example.com, which the system's email check rejects (null MX), so the same name was used with @gmail.com (operations.bilishatid@gmail.com); mail went to the isolated test log only. Screenshot: TC-LOG-001.jpg Recovered evidence from the prior recorded browser run; reviewed in this continuation, not rerun as a fresh account test.
A3: TC-LOG-002 | B3: Required Fields | C3: Submit a completely empty form | D3: Equivalence Partitioning | E3: High | F3: The logistics registration page is open. | G3: 1. Leave every field blank and every dropdown on its default option. 2. Click Register. | H3: All fields blank | I3: Registration is blocked. A required-field message is shown for every mandatory field. No account is created and no OTP is sent. | J3: A1 | K3: Submitting the courier application with every field left as it opened showed all required-field messages at once: Company name is required. / Use 2 to 6 letters or numbers (for example JNT). / Province is required. / City or municipality is required. / Barangay is required. / Street or building address is required. / Upload your DTI, SEC or Mayor's Permit. No application was created. | L3: Pass | M3: Contact email and contact number are pre-filled from the applicant's account (qa.acct_logistics.101@gmail.com, +639521000101), so they are never blank. The account step (name, email, mobile, password) behaves as in TC-BUY-002. Screenshot: TC-LOG-002.jpg Recovered evidence from the prior recorded browser run; reviewed in this continuation, not rerun as a fresh account test.
A4: TC-LOG-003 | B4: Required Fields | C4: Leave one required field blank at a time | D4: Equivalence Partitioning | E4: High | F4: The logistics registration page is open. | G4: 1. Fill in all fields with valid data. 2. Clear one required field. 3. Click Register. 4. Repeat for each field in the test data. | H4: Clear in turn: Company Name SEC Registration No. TIN Region Province City / Municipality Barangay Street Address Postal Code Contact Person First Name Contact Person Last Name Position Email Mobile Number Service Areas SEC Certificate (upload) BIR Form 2303 (upload) Mayor's / Business Permit (upload) Valid ID of Authorized Representative (upload) Password Confirm Password | I4: Each time, registration is blocked and a required-field message is shown on the blank field only. Other entered values (except passwords and uploads) are kept. No account is created. | J4: A1 | K4: Company Name: blocked – Company name is required.; Short code: blocked – Use 2 to 6 letters or numbers (for example JNT). (company name kept: yes); Region/Province/City/Barangay: blocked – Province is required. / City or municipality is required. / Barangay is required. (company name kept: yes); Street Address: blocked – Street or building address is required. (company name kept: yes); Business permit: blocked – Upload your DTI, SEC or Mayor's Permit. (company name kept: yes); Contact email and contact number: when emptied they immediately refill with the account's own values (qa.acct_logistics.102@gmail.com, +639521000102), so they cannot be left blank. The account-step fields (contact person first and last name, email, mobile, password, confirm password) each block with a message on that field only, as in TC-BUY-003. | L4: Pass | M4: SEC Registration No., TIN, Postal Code, Position, Service Areas, BIR Form 2303 and the representative's ID upload are not on the form. Screenshot: TC-LOG-003.jpg Recovered evidence from the prior recorded browser run; reviewed in this continuation, not rerun as a fresh account test.
A5: TC-LOG-004 | B5: Name | C5: Name with numbers or symbols | D5: Equivalence Partitioning | E5: Medium | F5: The logistics registration page is open. | G5: 1. Fill in all other fields with valid data. 2. Enter the test data in the name fields. 3. Click Register. | H5: First Name: Carlos Antonio7 Last Name: Dela Cruz@# | I5: Registration is blocked. A message on each name field says only letters are allowed. | J5: A2 | K5: Registration was accepted; the account was saved with first name "Carlos Antonio7" and last name "Dela Cruz@#". No message about letters only was shown. | L5: Fail | M5: Defect: name fields accept digits and symbols. In Loved-IT a logistics partner is a courier company: the contact person first creates a Loved-IT account at /register (name, email, mobile, password) and then applies at /register/courier; this field is on the account step, so the case was run there with the logistics test data. Screenshot: TC-LOG-004.jpg Recovered evidence from the prior recorded browser run; reviewed in this continuation, not rerun as a fresh account test.
A6: TC-LOG-005 | B6: Name | C6: Name with ñ and allowed punctuation | D6: Equivalence Partitioning | E6: Low | F6: The logistics registration page is open. The email, mobile number and other unique values in the test data are not yet registered. | G6: 1. Fill in all other fields with valid data. 2. Enter the test data in the name fields. 3. Click Register. | H6: First Name: Iñigo Rafael Last Name: Muñoz-D'Angelo | I6: The names are accepted and saved exactly as typed, including ñ. | J6: A2 | K6: Registration was accepted and the names were saved as "Iñigo Rafael" and "Muñoz-D'Angelo". | L6: Pass | M6: In Loved-IT a logistics partner is a courier company: the contact person first creates a Loved-IT account at /register (name, email, mobile, password) and then applies at /register/courier; this field is on the account step, so the case was run there with the logistics test data. Screenshot: TC-LOG-005.jpg Recovered evidence from the prior recorded browser run; reviewed in this continuation, not rerun as a fresh account test.
A7: TC-LOG-006 | B7: Name | C7: Name length at the limits | D7: Boundary Value Analysis | E7: Medium | F7: The logistics registration page is open. The email, mobile number and other unique values in the test data are not yet registered. | G7: 1. Fill in all other fields with valid data. 2. Enter each first name in the test data, one per attempt. 3. Click Register. | H7: 1 character: C (reject) 2 characters: Co (accept) 50 characters: Maria Cristina Angelica Bernadette Josefina Leonor (accept) 51 characters: Maria Cristina Angelica Bernadette Josefina Leonora (reject) | I7: 1 and 51 characters are rejected with a length message. 2 and 50 characters are accepted. | J7: A2 | K7: 1 character: accepted; 2 characters: accepted; 50 characters: accepted; 51 characters: rejected ("The first name field must not be greater than 50 characters."). | L7: Fail | M7: Defect: a 1-character name is accepted. In Loved-IT a logistics partner is a courier company: the contact person first creates a Loved-IT account at /register (name, email, mobile, password) and then applies at /register/courier; this field is on the account step, so the case was run there with the logistics test data. Screenshot: TC-LOG-006.jpg Recovered evidence from the prior recorded browser run; reviewed in this continuation, not rerun as a fresh account test.
A8: TC-LOG-007 | B8: Email | C8: Email in an invalid format | D8: Equivalence Partitioning | E8: High | F8: The logistics registration page is open. | G8: 1. Fill in all other fields with valid data. 2. Enter each email in the test data, one per attempt. 3. Click Register. | H8: operations.bilishatidexample.com (no @) operations.bilishatid@ (no domain) @example.com (no name) operations.bilishatid@example (no .com) operations bilishatid@example.com (space) | I8: Each value is rejected with a message asking for a valid email address. No account is created. | J8: A3 | K8: "operations.bilishatidgmail.com": rejected (Please include an '@' in the email address. 'operations.bilishatidgmail.com' is missing an '@'.); "operations.bilishatid@": rejected (Please enter a part following '@'. 'operations.bilishatid@' is incomplete.); "@gmail.com": rejected (Please enter a part followed by '@'. '@gmail.com' is incomplete.); "operations.bilishatid@example": rejected (The email field must be a valid email address.); "operations bilishatid@gmail.com": rejected (A part followed by '@' should not contain the symbol ' '.). No account was created. | L8: Pass | M8: In Loved-IT a logistics partner is a courier company: the contact person first creates a Loved-IT account at /register (name, email, mobile, password) and then applies at /register/courier; this field is on the account step, so the case was run there with the logistics test data. @gmail.com used in place of @example.com. Screenshot: TC-LOG-007.jpg Recovered evidence from the prior recorded browser run; reviewed in this continuation, not rerun as a fresh account test.
A9: TC-LOG-008 | B9: Email | C9: Email that is already registered | D9: Equivalence Partitioning | E9: High | F9: The logistics registration page is open. The logistics account operations@bilishatid.example.com (Bilis Hatid Express Inc.) already exists. | G9: 1. Fill in all other fields with valid data. 2. Enter the existing email. 3. Click Register. | H9: Email: operations@bilishatid.example.com | I9: Registration is blocked. A message says the email is already in use. No account is created. | J9: A3 | K9: The existing email was treated as a duplicate and registration was blocked: "The email has already been taken.". Accounts with this email: 1. | L9: Pass | M9: In Loved-IT a logistics partner is a courier company: the contact person first creates a Loved-IT account at /register (name, email, mobile, password) and then applies at /register/courier; this field is on the account step, so the case was run there with the logistics test data. The test-data addresses use example.com, which the system's email check rejects (null MX), so the same name was used with @gmail.com (operations.bilishatid@gmail.com); mail went to the isolated test log only. Screenshot: TC-LOG-008.jpg Recovered evidence from the prior recorded browser run; reviewed in this continuation, not rerun as a fresh account test.
A10: TC-LOG-009 | B10: Email | C10: Registered email typed in capital letters | D10: Error Guessing | E10: Medium | F10: The logistics registration page is open. The logistics account operations@bilishatid.example.com (Bilis Hatid Express Inc.) already exists. | G10: 1. Fill in all other fields with valid data. 2. Enter the same email in capital letters. 3. Click Register. | H10: Email: OPERATIONS@BILISHATID.EXAMPLE.COM | I10: The email is treated as a duplicate. Registration is blocked. | J10: A3 | K10: The capitalised email was treated as a duplicate and registration was blocked: "The email has already been taken.". Accounts with this email: 1. | L10: Pass | M10: In Loved-IT a logistics partner is a courier company: the contact person first creates a Loved-IT account at /register (name, email, mobile, password) and then applies at /register/courier; this field is on the account step, so the case was run there with the logistics test data. The test-data addresses use example.com, which the system's email check rejects (null MX), so the same name was used with @gmail.com (operations.bilishatid@gmail.com); mail went to the isolated test log only. Screenshot: TC-LOG-009.jpg Recovered evidence from the prior recorded browser run; reviewed in this continuation, not rerun as a fresh account test.
A11: TC-LOG-010 | B11: Email | C11: Email with spaces before and after | D11: Error Guessing | E11: Low | F11: The logistics registration page is open. The email, mobile number and other unique values in the test data are not yet registered. | G11: 1. Fill in all other fields with valid data. 2. Type two spaces before and after the email. 3. Click Register. | H11: Email: " logistics.test01@example.com " | I11: The spaces are removed and the email is saved as logistics.test01@example.com. | J11: A3 | K11: Registration was accepted and the email was saved as "logistics.test01@gmail.com" with no spaces. | L11: Pass | M11: In Loved-IT a logistics partner is a courier company: the contact person first creates a Loved-IT account at /register (name, email, mobile, password) and then applies at /register/courier; this field is on the account step, so the case was run there with the logistics test data. Screenshot: TC-LOG-010.jpg Recovered evidence from the prior recorded browser run; reviewed in this continuation, not rerun as a fresh account test.
A12: TC-LOG-011 | B12: Mobile Number | C12: Mobile number in an invalid format | D12: Equivalence Partitioning | E12: High | F12: The logistics registration page is open. | G12: 1. Fill in all other fields with valid data. 2. Enter each mobile number in the test data, one per attempt. 3. Click Register. | H12: 0917ABC4567 (letters) 0917-123-456 (symbols, too short) 12345678901 (does not start with 09) 02-8123-4567 (landline) | I12: Each value is rejected with a message asking for a valid mobile number. | J12: A4 | K12: "0928ABC5123": accepted and saved as +6309285123; "0928-765-111": accepted and saved as +630928765111; "32345678901": accepted and saved as +633234567890; "02-8555-1234": accepted and saved as +630285551234. | L12: Fail | M12: Defect: letters and symbols are dropped silently and the digits are saved after +63; landlines and numbers not starting with 9 are accepted. Values equivalent to the test data were used (the 0917... ones were already saved in earlier tests). In Loved-IT a logistics partner is a courier company: the contact person first creates a Loved-IT account at /register (name, email, mobile, password) and then applies at /register/courier; this field is on the account step, so the case was run there with the logistics test data. Screenshot: TC-LOG-011.jpg Recovered evidence from the prior recorded browser run; reviewed in this continuation, not rerun as a fresh account test.
... A45: TC-LOG-044 | B45: Access Control | C45: Open another role's pages | D45: Error Guessing | E45: Medium | F45: The Approved logistics account operations@bilishatid.example.com is logged in. | G45: 1. Paste the address of each dashboard in the test data into the browser, one at a time. | H45: Admin dashboard Seller dashboard Rider dashboard | I45: Access is denied each time (error 403 or redirect). No data from the other role is shown. | J45: A16 | K45: Admin dashboard (/admin): redirected to /; Seller dashboard (/seller): redirected to /register/seller; Rider dashboard (/rider/dashboard): redirected to /register/rider. API: admin 404, seller 404. No data from another role was shown. | L45: Pass | M45: Screenshots: TC-LOG-044-*.jpg Recovered evidence from the prior recorded browser run; reviewed in this continuation, not rerun as a fresh account test.
